Workbook

Sheet Hoja1
A1: Módulo del formulario de aplicación | B1: Código del formulario de aplicación | C1: Número del formulario de aplicación | D1: Código de cliente | E1: Razón Social | F1: Vendedor | G1: Código de imputación | H1: Código de subcuenta | I1: Fecha de Movimiento | J1: Saldo Nacional | K1: Acumulado Nacional | L1: Sucursal | M1: Numero completo factura (suc+num)
A2: VT | B2: ANTMI | C2: 4881 | D2: I/167 | E2: =VLOOKUP(D:D,Hoja2!A:B,2,FALSE) -> ANGLADA ALFONSO | F2: V1 | G2: CC | H2: I/167 | I2: 2/2/2018 | J2: -2.5 | K2: -2.5 | M2: -00004881
A3: VT | B3: NDB17 | C3: 15 | D3: I/167 | E3: =VLOOKUP(D:D,Hoja2!A:B,2,FALSE) -> ANGLADA ALFONSO | F3: V1 | G3: CC | H3: I/167 | I3: 21/9/2019 | J3: 2.5 | K3: 0 | L3: 0017 | M3: 0017-00000015
A4: VT | B4: FA17 | C4: 3790 | D4: I/169 | E4: =VLOOKUP(D:D,Hoja2!A:B,2,FALSE) -> ARDAPEZ SA | F4: JOGR | G4: CC | H4: I/169 | I4: 18/1/2023 | J4: 1734000 | K4: 1734000 | L4: 0017 | M4: 0017-00003790
A5: VT | B5: NCA17 | C5: 168 | D5: I/169 | E5: =VLOOKUP(D:D,Hoja2!A:B,2,FALSE) -> ARDAPEZ SA | F5: JOGR | G5: CC | H5: I/169 | I5: 18/1/2023 | J5: -1734000 | K5: 0 | L5: 0017 | M5: 0017-00000168
A6: VT | B6: FA17 | C6: 7224 | D6: I/227 | E6: =VLOOKUP(D:D,Hoja2!A:B,2,FALSE) -> MARDI SA | F6: JOGR | G6: CC | H6: I/227 | I6: 22/4/2026 | J6: 19324800 | K6: 19324800 | L6: 0017 | M6: 0017-00007224
A7: VT | B7: FA17 | C7: 7240 | D7: I/227 | E7: =VLOOKUP(D:D,Hoja2!A:B,2,FALSE) -> MARDI SA | F7: JOGR | G7: CC | H7: I/227 | I7: 29/4/2026 | J7: 23015300 | K7: 42340100 | L7: 0017 | M7: 0017-00007240
A8: VT | B8: FA17 | C8: 7257 | D8: I/227 | E8: =VLOOKUP(D:D,Hoja2!A:B,2,FALSE) -> MARDI SA | F8: JOGR | G8: CC | H8: I/227 | I8: 4/5/2026 | J8: 20431950 | K8: 62772050 | L8: 0017 | M8: 0017-00007257
A9: VT | B9: FA17 | C9: 7284 | D9: I/227 | E9: =VLOOKUP(D:D,Hoja2!A:B,2,FALSE) -> MARDI SA | F9: JOGR | G9: CC | H9: I/227 | I9: 6/5/2026 | J9: 24827000 | K9: 87599050 | L9: 0017 | M9: 0017-00007284
A10: VT | B10: FA17 | C10: 7302 | D10: I/227 | E10: =VLOOKUP(D:D,Hoja2!A:B,2,FALSE) -> MARDI SA | F10: JOGR | G10: CC | H10: I/227 | I10: 8/5/2026 | J10: 28819450 | K10: 116418500 | L10: 0017 | M10: 0017-00007302
A11: VT | B11: NCA17 | C11: 91 | D11: I/241 | E11: =VLOOKUP(D:D,Hoja2!A:B,2,FALSE) -> GIORNO SA | F11: JOMO | G11: CC | H11: I/241 | I11: 1/7/2020 | J11: -0.01 | K11: -0.01 | L11: 0017 | M11: 0017-00000091
A12: VT | B12: FA17 | C12: 2189 | D12: I/241 | E12: =VLOOKUP(D:D,Hoja2!A:B,2,FALSE) -> GIORNO SA | F12: JOMO | G12: CC | H12: I/241 | I12: 28/8/2020 | J12: 1274713.2 | K12: 1274713.2 | L12: 0017 | M12: 0017-00002189
A13: VT | B13: FA17 | C13: 2191 | D13: I/241 | E13: =VLOOKUP(D:D,Hoja2!A:B,2,FALSE) -> GIORNO SA | F13: JOMO | G13: CC | H13: I/241 | I13: 31/8/2020 | J13: 2574624.3 | K13: 3849337.5 | L13: 0017 | M13: 0017-00002191
A14: VT | B14: NCA17 | C14: 99 | D14: I/241 | E14: =VLOOKUP(D:D,Hoja2!A:B,2,FALSE) -> GIORNO SA | F14: JOMO | G14: CC | H14: I/241 | I14: 31/8/2020 | J14: -1316317.5 | K14: 2533020 | L14: 0017 | M14: 0017-00000099
... A23: VT | B23: FA17 | C23: 7303 | D23: I/443 | E23: =VLOOKUP(D:D,Hoja2!A:B,2,FALSE) -> NATUSUR SA | F23: JOGR | G23: CC | H23: I/443 | I23: 8/5/2026 | J23: 31118945 | K23: 75097680 | L23: 0017 | M23: 0017-00007303
A24: VT | B24: FAINI | C24: 783 | D24: I/444 | E24: =VLOOKUP(D:D,Hoja2!A:B,2,FALSE) -> AGUSTINER SA | G24: CCE | H24: I/444 | I24: 13/10/2016 | J24: 280180.58 | K24: 280180.58 | L24: 0018 | M24: 0018-00000783
A25: VT | B25: FAINI | C25: 839 | D25: I/444 | E25: =VLOOKUP(D:D,Hoja2!A:B,2,FALSE) -> AGUSTINER SA | G25: CCE | H25: I/444 | I25: 16/11/2016 | J25: 288058.22 | K25: 568238.8 | L25: 0018 | M25: 0018-00000839
A26: VT | B26: FAINI | C26: 847 | D26: I/444 | E26: =VLOOKUP(D:D,Hoja2!A:B,2,FALSE) -> AGUSTINER SA | G26: CCE | H26: I/444 | I26: 6/12/2016 | J26: 287907.42 | K26: 856146.22 | L26: 0018 | M26: 0018-00000847
A27: VT | B27: FAINI | C27: 848 | D27: I/444 | E27: =VLOOKUP(D:D,Hoja2!A:B,2,FALSE) -> AGUSTINER SA | G27: CCE | H27: I/444 | I27: 14/12/2016 | J27: 57987.09 | K27: 914133.31 | L27: 0018 | M27: 0018-00000848
A28: VT | B28: FAINI | C28: 10000632 | D28: I/448 | E28: =VLOOKUP(D:D,Hoja2!A:B,2,FALSE) -> ARHEHPEZ SA | G28: CC | H28: I/448 | I28: 23/1/2014 | J28: 121 | K28: 121 | L28: 0018 | M28: 0018-10000632
A29: VT | B29: FAINI | C29: 10000636 | D29: I/448 | E29: =VLOOKUP(D:D,Hoja2!A:B,2,FALSE) -> ARHEHPEZ SA | G29: CC | H29: I/448 | I29: 27/1/2014 | J29: 12584 | K29: 12705 | L29: 0018 | M29: 0018-10000636
A30: VT | B30: FA17 | C30: 208 | D30: I/468 | E30: =VLOOKUP(D:D,Hoja2!A:B,2,FALSE) -> FRIGOSUR SRL | F30: V1 | G30: CC | H30: I/468 | I30: 29/8/2017 | J30: 125090.63 | K30: 125090.63 | L30: 0017 | M30: 0017-00000208
A31: VT | B31: FA17 | C31: 223 | D31: I/468 | E31: =VLOOKUP(D:D,Hoja2!A:B,2,FALSE) -> FRIGOSUR SRL | F31: V1 | G31: CC | H31: I/468 | I31: 29/8/2017 | J31: 126985.94 | K31: 252076.57 | L31: 0017 | M31: 0017-00000223
A32: VT | B32: FA17 | C32: 208 | D32: I/468 | E32: =VLOOKUP(D:D,Hoja2!A:B,2,FALSE) -> FRIGOSUR SRL | F32: V1 | G32: CCE | H32: I/468 | I32: 6/9/2017 | J32: -125090.63 | K32: 126985.94 | L32: 0017 | M32: 0017-00000208
A33: VT | B33: FA17 | C33: 223 | D33: I/468 | E33: =VLOOKUP(D:D,Hoja2!A:B,2,FALSE) -> FRIGOSUR SRL | F33: V1 | G33: CCE | H33: I/468 | I33: 6/9/2017 | J33: -126985.94 | K33: 0 | L33: 0017 | M33: 0017-00000223
A34: VT | B34: FA17 | C34: 7276 | D34: I/468 | E34: =VLOOKUP(D:D,Hoja2!A:B,2,FALSE) -> FRIGOSUR SRL | F34: V1 | G34: CC | H34: I/468 | I34: 6/5/2026 | J34: 24928750 | K34: 24928750 | L34: 0017 | M34: 0017-00007276
A35: VT | B35: FA17 | C35: 7295 | D35: I/468 | E35: =VLOOKUP(D:D,Hoja2!A:B,2,FALSE) -> FRIGOSUR SRL | F35: V1 | G35: CC | H35: I/468 | I35: 8/5/2026 | J35: 28634375 | K35: 53563125 | L35: 0017 | M35: 0017-00007295
A36: VT | B36: FAINI | C36: 100000001 | D36: I/509 | E36: =VLOOKUP(D:D,Hoja2!A:B,2,FALSE) -> O. Y J. DI MARCO | G36: CC | H36: I/509 | I36: 1/1/2001 | J36: 13522.44 | K36: 13522.44 | L36: 0018 | M36: 0018-00000001
A37: VT | B37: NCA18 | C37: 49 | D37: I/509 | E37: =VLOOKUP(D:D,Hoja2!A:B,2,FALSE) -> O. Y J. DI MARCO | G37: CC | H37: I/509 | I37: 30/5/2022 | J37: -13522.44 | K37: 0 | L37: 0018 | M37: 0018-00000049
A38: VT | B38: FA17 | C38: 2118 | D38: I/58 | E38: =VLOOKUP(D:D,Hoja2!A:B,2,FALSE) -> ANTONIO MIRALLES SA | F38: SEGU | G38: CC | H38: I/58 | I38: 28/7/2020 | J38: 5531256.7 | K38: 5531256.7 | L38: 0017 | M38: 0017-00002118
A39: VT | B39: NCA17 | C39: 96 | D39: I/58 | E39: =VLOOKUP(D:D,Hoja2!A:B,2,FALSE) -> ANTONIO MIRALLES SA | F39: SEGU | G39: CC | H39: I/58 | I39: 30/7/2020 | J39: -5531256.7 | K39: -0.0099999998 | L39: 0017 | M39: 0017-00000096
A40: VT | B40: AJUIN+ | C40: 28 | D40: I/58 | E40: =VLOOKUP(D:D,Hoja2!A:B,2,FALSE) -> ANTONIO MIRALLES SA | F40: SEGU | G40: CCE | H40: I/58 | I40: 6/11/2024 | J40: 0.01 | K40: 2.2351742e-10 | L40: 0013 | M40: 0013-00000028
A41: VT | B41: FAINI | C41: 1065 | D41: I/596 | E41: =VLOOKUP(D:D,Hoja2!A:B,2,FALSE) -> 27 DE NOVIEMBRE SA | F41: JOGR | G41: CCE | H41: I/596 | I41: 12/5/2017 | J41: 0.01 | K41: 0.01 | L41: 0018 | M41: 0018-00001065
A42: VT | B42: FAINI | C42: 1079 | D42: I/596 | E42: =VLOOKUP(D:D,Hoja2!A:B,2,FALSE) -> 27 DE NOVIEMBRE SA | F42: JOGR | G42: CCE | H42: I/596 | I42: 23/5/2017 | J42: -0.01 | K42: 0 | L42: 0018 | M42: 0018-00001079
A43: VT | B43: FA17 | C43: 204 | D43: I/596 | E43: =VLOOKUP(D:D,Hoja2!A:B,2,FALSE) -> 27 DE NOVIEMBRE SA | F43: JOGR | G43: CC | H43: I/596 | I43: 29/8/2017 | J43: 111104 | K43: 111104 | L43: 0017 | M43: 0017-00000204
A44: VT | B44: FA17 | C44: 204 | D44: I/596 | E44: =VLOOKUP(D:D,Hoja2!A:B,2,FALSE) -> 27 DE NOVIEMBRE SA | F44: JOGR | G44: CCE | H44: I/596 | I44: 4/9/2017 | J44: -111104 | K44: 0 | L44: 0017 | M44: 0017-00000204
A45: VT | B45: FA17 | C45: 798 | D45: I/596 | E45: =VLOOKUP(D:D,Hoja2!A:B,2,FALSE) -> 27 DE NOVIEMBRE SA | F45: JOGR | G45: CC | H45: I/596 | I45: 17/9/2018 | J45: 230384 | K45: 230384 | L45: 0017 | M45: 0017-00000798
A46: VT | B46: NCA17 | C46: 40 | D46: I/596 | E46: =VLOOKUP(D:D,Hoja2!A:B,2,FALSE) -> 27 DE NOVIEMBRE SA | F46: JOGR | G46: CC | H46: I/596 | I46: 20/9/2018 | J46: -230384 | K46: 0 | L46: 0017 | M46: 0017-00000040
A47: VT | B47: ANTMI | C47: 6713 | D47: I/596 | E47: =VLOOKUP(D:D,Hoja2!A:B,2,FALSE) -> 27 DE NOVIEMBRE SA | F47: JOGR | G47: CC | H47: I/596 | I47: 1/2/2022 | J47: -15541.35 | K47: -15541.35 | M47: -00006713
A48: VT | B48: FA17 | C48: 3052 | D48: I/596 | E48: =VLOOKUP(D:D,Hoja2!A:B,2,FALSE) -> 27 DE NOVIEMBRE SA | F48: JOGR | G48: CC | H48: I/596 | I48: 10/2/2022 | J48: 15541.35 | K48: 0 | L48: 0017 | M48: 0017-00003052
...

Sheet Hoja2
A1: Cuenta | B1: Razón Social
A2: I/860 | B2: PESQUERA EL GRINGO SRL
A3: E/1042 | B3: PACIFIC AMERICAN FISH COMPANY, INC
A4: E/1044 | B4: OCEANPRO FOODS (HONGKONG) CO. LIMITED
A5: E/1045 | B5: OCEANPRO GROUP CO., LIMITED
A6: E/1055 | B6: MORFISH LLC
A7: E/1077 | B7: PRODAKVA LTD.
A8: E/1111 | B8: MICHAEL THOMAS EISSLER FARIAS
A9: E/1114 | B9: GRAND PARTNER AS
A10: E/1125 | B10: ARTI SEAFOOD GMBH
A11: I/7363 | B11: RICH MARINE FISHERY S.A.
A12: I/7364 | B12: PESQUERA BUENAVISTA S.A
... A822: I/7190 | B822: COOP.TRABAJO EL PEHUEN LT
